[2022-12-20T15:03:56.096+0000] {taskinstance.py:1087} INFO - Dependencies all met for <TaskInstance: co2balance.ExtractData manual__2022-12-20T15:03:53.559675+00:00 [queued]>
[2022-12-20T15:03:56.119+0000] {taskinstance.py:1087} INFO - Dependencies all met for <TaskInstance: co2balance.ExtractData manual__2022-12-20T15:03:53.559675+00:00 [queued]>
[2022-12-20T15:03:56.126+0000] {taskinstance.py:1283} INFO - 
--------------------------------------------------------------------------------
[2022-12-20T15:03:56.126+0000] {taskinstance.py:1284} INFO - Starting attempt 1 of 1
[2022-12-20T15:03:56.126+0000] {taskinstance.py:1285} INFO - 
--------------------------------------------------------------------------------
[2022-12-20T15:03:56.190+0000] {taskinstance.py:1304} INFO - Executing <Task(PythonOperator): ExtractData> on 2022-12-20 15:03:53.559675+00:00
[2022-12-20T15:03:56.199+0000] {standard_task_runner.py:55} INFO - Started process 2944 to run task
[2022-12-20T15:03:56.203+0000] {standard_task_runner.py:82} INFO - Running: ['***', 'tasks', 'run', 'co2balance', 'ExtractData', 'manual__2022-12-20T15:03:53.559675+00:00', '--job-id', '24', '--raw', '--subdir', 'DAGS_FOLDER/co2balance.py', '--cfg-path', '/tmp/tmpt4uv4_wx']
[2022-12-20T15:03:56.206+0000] {standard_task_runner.py:83} INFO - Job 24: Subtask ExtractData
[2022-12-20T15:03:56.332+0000] {task_command.py:389} INFO - Running <TaskInstance: co2balance.ExtractData manual__2022-12-20T15:03:53.559675+00:00 [running]> on host 1a27c7ed0719
[2022-12-20T15:03:56.479+0000] {taskinstance.py:1513} INFO - Exporting the following env vars:
AIRFLOW_CTX_DAG_OWNER=CO2balance
AIRFLOW_CTX_DAG_ID=co2balance
AIRFLOW_CTX_TASK_ID=ExtractData
AIRFLOW_CTX_EXECUTION_DATE=2022-12-20T15:03:53.559675+00:00
AIRFLOW_CTX_TRY_NUMBER=1
AIRFLOW_CTX_DAG_RUN_ID=manual__2022-12-20T15:03:53.559675+00:00
[2022-12-20T15:03:56.484+0000] {taskinstance.py:1772} ERROR - Task failed with exception
Traceback (most recent call last):
  File "/home/airflow/.local/lib/python3.7/site-packages/airflow/operators/python.py", line 175, in execute
    return_value = self.execute_callable()
  File "/home/airflow/.local/lib/python3.7/site-packages/airflow/operators/python.py", line 192, in execute_callable
    return self.python_callable(*self.op_args, **self.op_kwargs)
  File "/opt/airflow/dags/app/populate/cook_stove/clean_project_file.py", line 119, in extract_project_data
    raw_data = pd.read_excel(file_path, sheet_name='project_data')
  File "/home/airflow/.local/lib/python3.7/site-packages/pandas/util/_decorators.py", line 311, in wrapper
    return func(*args, **kwargs)
  File "/home/airflow/.local/lib/python3.7/site-packages/pandas/io/excel/_base.py", line 364, in read_excel
    io = ExcelFile(io, storage_options=storage_options, engine=engine)
  File "/home/airflow/.local/lib/python3.7/site-packages/pandas/io/excel/_base.py", line 1192, in __init__
    content_or_path=path_or_buffer, storage_options=storage_options
  File "/home/airflow/.local/lib/python3.7/site-packages/pandas/io/excel/_base.py", line 1071, in inspect_excel_format
    content_or_path, "rb", storage_options=storage_options, is_text=False
  File "/home/airflow/.local/lib/python3.7/site-packages/pandas/io/common.py", line 711, in get_handle
    handle = open(handle, ioargs.mode)
FileNotFoundError: [Errno 2] No such file or directory: '../../app/data/co2balance.xlsx'
[2022-12-20T15:03:56.504+0000] {taskinstance.py:1327} INFO - Marking task as FAILED. dag_id=co2balance, task_id=ExtractData, execution_date=20221220T150353, start_date=20221220T150356, end_date=20221220T150356
[2022-12-20T15:03:56.523+0000] {standard_task_runner.py:105} ERROR - Failed to execute job 24 for task ExtractData ([Errno 2] No such file or directory: '../../app/data/co2balance.xlsx'; 2944)
[2022-12-20T15:03:56.540+0000] {local_task_job.py:159} INFO - Task exited with return code 1
[2022-12-20T15:03:56.566+0000] {taskinstance.py:2582} INFO - 0 downstream tasks scheduled from follow-on schedule check
