[2022-12-20 09:20:11,908] {taskinstance.py:1159} INFO - Dependencies all met for <TaskInstance: co2balance.clean_data manual__2022-12-20T09:20:11.211192+00:00 [queued]>
[2022-12-20 09:20:11,932] {taskinstance.py:1159} INFO - Dependencies all met for <TaskInstance: co2balance.clean_data manual__2022-12-20T09:20:11.211192+00:00 [queued]>
[2022-12-20 09:20:11,932] {taskinstance.py:1356} INFO - 
--------------------------------------------------------------------------------
[2022-12-20 09:20:11,932] {taskinstance.py:1357} INFO - Starting attempt 1 of 1
[2022-12-20 09:20:11,933] {taskinstance.py:1358} INFO - 
--------------------------------------------------------------------------------
[2022-12-20 09:20:11,969] {taskinstance.py:1377} INFO - Executing <Task(BashOperator): clean_data> on 2022-12-20 09:20:11.211192+00:00
[2022-12-20 09:20:11,976] {standard_task_runner.py:52} INFO - Started process 654 to run task
[2022-12-20 09:20:11,987] {standard_task_runner.py:79} INFO - Running: ['***', 'tasks', 'run', 'co2balance', 'clean_data', 'manual__2022-12-20T09:20:11.211192+00:00', '--job-id', '7', '--raw', '--subdir', 'DAGS_FOLDER/test.py', '--cfg-path', '/tmp/tmp1ct2h7cs', '--error-file', '/tmp/tmpmuyj6rc1']
[2022-12-20 09:20:11,988] {standard_task_runner.py:80} INFO - Job 7: Subtask clean_data
[2022-12-20 09:20:12,110] {task_command.py:369} INFO - Running <TaskInstance: co2balance.clean_data manual__2022-12-20T09:20:11.211192+00:00 [running]> on host 800c7fb31dfc
[2022-12-20 09:20:12,303] {taskinstance.py:1571} INFO - Exporting the following env vars:
AIRFLOW_CTX_DAG_OWNER=CO2balance
AIRFLOW_CTX_DAG_ID=co2balance
AIRFLOW_CTX_TASK_ID=clean_data
AIRFLOW_CTX_EXECUTION_DATE=2022-12-20T09:20:11.211192+00:00
AIRFLOW_CTX_TRY_NUMBER=1
AIRFLOW_CTX_DAG_RUN_ID=manual__2022-12-20T09:20:11.211192+00:00
[2022-12-20 09:20:12,304] {subprocess.py:62} INFO - Tmp dir root location: 
 /tmp
[2022-12-20 09:20:12,305] {subprocess.py:74} INFO - Running command: ['bash', '-c', 'python3 /home/chris/DEV/co2balance/pipeline/app/populate/cook_stove/clean_project_file.py']
[2022-12-20 09:20:12,324] {subprocess.py:85} INFO - Output:
[2022-12-20 09:20:12,358] {subprocess.py:92} INFO - python3: can't open file '/home/chris/DEV/co2balance/pipeline/app/populate/cook_stove/clean_project_file.py': [Errno 2] No such file or directory
[2022-12-20 09:20:12,361] {subprocess.py:96} INFO - Command exited with return code 2
[2022-12-20 09:20:12,390] {taskinstance.py:1889} ERROR - Task failed with exception
Traceback (most recent call last):
  File "/home/airflow/.local/lib/python3.7/site-packages/airflow/operators/bash.py", line 195, in execute
    f'Bash command failed. The command returned a non-zero exit code {result.exit_code}.'
airflow.exceptions.AirflowException: Bash command failed. The command returned a non-zero exit code 2.
[2022-12-20 09:20:12,396] {taskinstance.py:1400} INFO - Marking task as FAILED. dag_id=co2balance, task_id=clean_data, execution_date=20221220T092011, start_date=20221220T092011, end_date=20221220T092012
[2022-12-20 09:20:12,415] {standard_task_runner.py:97} ERROR - Failed to execute job 7 for task clean_data (Bash command failed. The command returned a non-zero exit code 2.; 654)
[2022-12-20 09:20:12,441] {local_task_job.py:156} INFO - Task exited with return code 1
[2022-12-20 09:20:12,548] {local_task_job.py:273} INFO - 0 downstream tasks scheduled from follow-on schedule check
