[2022-12-20T13:07:41.670+0000] {taskinstance.py:1087} INFO - Dependencies all met for <TaskInstance: co2balance.initialise_db manual__2022-12-20T13:07:39.319333+00:00 [queued]>
[2022-12-20T13:07:41.685+0000] {taskinstance.py:1087} INFO - Dependencies all met for <TaskInstance: co2balance.initialise_db manual__2022-12-20T13:07:39.319333+00:00 [queued]>
[2022-12-20T13:07:41.685+0000] {taskinstance.py:1283} INFO - 
--------------------------------------------------------------------------------
[2022-12-20T13:07:41.686+0000] {taskinstance.py:1284} INFO - Starting attempt 1 of 1
[2022-12-20T13:07:41.686+0000] {taskinstance.py:1285} INFO - 
--------------------------------------------------------------------------------
[2022-12-20T13:07:41.710+0000] {taskinstance.py:1304} INFO - Executing <Task(PythonOperator): initialise_db> on 2022-12-20 13:07:39.319333+00:00
[2022-12-20T13:07:41.718+0000] {standard_task_runner.py:55} INFO - Started process 1887 to run task
[2022-12-20T13:07:41.721+0000] {standard_task_runner.py:82} INFO - Running: ['***', 'tasks', 'run', 'co2balance', 'initialise_db', 'manual__2022-12-20T13:07:39.319333+00:00', '--job-id', '4', '--raw', '--subdir', 'DAGS_FOLDER/co2balance.py', '--cfg-path', '/tmp/tmp8p6ld409']
[2022-12-20T13:07:41.723+0000] {standard_task_runner.py:83} INFO - Job 4: Subtask initialise_db
[2022-12-20T13:07:41.846+0000] {task_command.py:389} INFO - Running <TaskInstance: co2balance.initialise_db manual__2022-12-20T13:07:39.319333+00:00 [running]> on host 980fbd331d58
[2022-12-20T13:07:41.956+0000] {taskinstance.py:1513} INFO - Exporting the following env vars:
AIRFLOW_CTX_DAG_OWNER=CO2balance
AIRFLOW_CTX_DAG_ID=co2balance
AIRFLOW_CTX_TASK_ID=initialise_db
AIRFLOW_CTX_EXECUTION_DATE=2022-12-20T13:07:39.319333+00:00
AIRFLOW_CTX_TRY_NUMBER=1
AIRFLOW_CTX_DAG_RUN_ID=manual__2022-12-20T13:07:39.319333+00:00
[2022-12-20T13:07:41.957+0000] {python.py:177} INFO - Done. Returned value was: <generator object get_db at 0x7faf79fac9d0>
[2022-12-20T13:07:41.968+0000] {taskinstance.py:1772} ERROR - Task failed with exception
Traceback (most recent call last):
  File "/home/airflow/.local/lib/python3.7/site-packages/airflow/utils/session.py", line 72, in wrapper
    return func(*args, **kwargs)
  File "/home/airflow/.local/lib/python3.7/site-packages/airflow/models/taskinstance.py", line 2301, in xcom_push
    session=session,
  File "/home/airflow/.local/lib/python3.7/site-packages/airflow/utils/session.py", line 72, in wrapper
    return func(*args, **kwargs)
  File "/home/airflow/.local/lib/python3.7/site-packages/airflow/models/xcom.py", line 240, in set
    map_index=map_index,
  File "/home/airflow/.local/lib/python3.7/site-packages/airflow/models/xcom.py", line 627, in serialize_value
    return json.dumps(value, cls=XComEncoder).encode("UTF-8")
  File "/usr/local/lib/python3.7/json/__init__.py", line 238, in dumps
    **kw).encode(obj)
  File "/home/airflow/.local/lib/python3.7/site-packages/airflow/utils/json.py", line 176, in encode
    return super().encode(o)
  File "/usr/local/lib/python3.7/json/encoder.py", line 199, in encode
    chunks = self.iterencode(o, _one_shot=True)
  File "/usr/local/lib/python3.7/json/encoder.py", line 257, in iterencode
    return _iterencode(o, 0)
  File "/home/airflow/.local/lib/python3.7/site-packages/airflow/utils/json.py", line 153, in default
    CLASSNAME: o.__module__ + "." + o.__class__.__qualname__,
AttributeError: 'generator' object has no attribute '__module__'
[2022-12-20T13:07:41.987+0000] {taskinstance.py:1327} INFO - Marking task as FAILED. dag_id=co2balance, task_id=initialise_db, execution_date=20221220T130739, start_date=20221220T130741, end_date=20221220T130741
[2022-12-20T13:07:42.000+0000] {standard_task_runner.py:105} ERROR - Failed to execute job 4 for task initialise_db ('generator' object has no attribute '__module__'; 1887)
[2022-12-20T13:07:42.013+0000] {local_task_job.py:159} INFO - Task exited with return code 1
[2022-12-20T13:07:42.037+0000] {taskinstance.py:2582} INFO - 0 downstream tasks scheduled from follow-on schedule check
